[0 : output] Output to be read-from/written-into folder '../chains', with prefix 'cpl-planckdesipantheon'
[3 : prior] *ERROR* Some arguments of the external prior 'cal_dip_prior' cannot be found and don't have a default value either: ['A_act']
[0 : prior] *ERROR* Some arguments of the external prior 'cal_dip_prior' cannot be found and don't have a default value either: ['A_act']
[1 : prior] *ERROR* Some arguments of the external prior 'cal_dip_prior' cannot be found and don't have a default value either: ['A_act']
[2 : prior] *ERROR* Some arguments of the external prior 'cal_dip_prior' cannot be found and don't have a default value either: ['A_act']
[2 : exception handler] *ERROR* Some arguments of the external prior 'cal_dip_prior' cannot be found and don't have a default value either: ['A_act']
[0 : exception handler] *ERROR* Some arguments of the external prior 'cal_dip_prior' cannot be found and don't have a default value either: ['A_act']
[3 : exception handler] *ERROR* Some arguments of the external prior 'cal_dip_prior' cannot be found and don't have a default value either: ['A_act']
[1 : exception handler] *ERROR* Some arguments of the external prior 'cal_dip_prior' cannot be found and don't have a default value either: ['A_act']
[0 : exception handler] ---------------------------------------

Traceback (most recent call last):
  File "/users/smp24dhl/.conda/envs/cosmos/bin/cobaya-run", line 8, in <module>
    sys.exit(run_script())
  File "/users/smp24dhl/.conda/envs/cosmos/lib/python3.9/site-packages/cobaya/run.py", line 198, in run_script
    run(info, **arguments.__dict__)
  File "/users/smp24dhl/.conda/envs/cosmos/lib/python3.9/site-packages/cobaya/run.py", line 123, in run
    with Model(updated_info["params"], updated_info["likelihood"],
  File "/users/smp24dhl/.conda/envs/cosmos/lib/python3.9/site-packages/cobaya/model.py", line 241, in __init__
    self.prior = Prior(self.parameterization, self._updated_info.get("prior"))
  File "/users/smp24dhl/.conda/envs/cosmos/lib/python3.9/site-packages/cobaya/prior.py", line 497, in __init__
    raise LoggedError(self.log, err, name, list(unknown))
cobaya.log.LoggedError: Some arguments of the external prior 'cal_dip_prior' cannot be found and don't have a default value either: ['A_act']
-------------------------------------------------------------

[3 : exception handler] ---------------------------------------

Traceback (most recent call last):
  File "/users/smp24dhl/.conda/envs/cosmos/bin/cobaya-run", line 8, in <module>
    sys.exit(run_script())
  File "/users/smp24dhl/.conda/envs/cosmos/lib/python3.9/site-packages/cobaya/run.py", line 198, in run_script
    run(info, **arguments.__dict__)
  File "/users/smp24dhl/.conda/envs/cosmos/lib/python3.9/site-packages/cobaya/run.py", line 123, in run
    with Model(updated_info["params"], updated_info["likelihood"],
  File "/users/smp24dhl/.conda/envs/cosmos/lib/python3.9/site-packages/cobaya/model.py", line 241, in __init__
    self.prior = Prior(self.parameterization, self._updated_info.get("prior"))
  File "/users/smp24dhl/.conda/envs/cosmos/lib/python3.9/site-packages/cobaya/prior.py", line 497, in __init__
    raise LoggedError(self.log, err, name, list(unknown))
cobaya.log.LoggedError: Some arguments of the external prior 'cal_dip_prior' cannot be found and don't have a default value either: ['A_act']
-------------------------------------------------------------

[1 : exception handler] ---------------------------------------

Traceback (most recent call last):
  File "/users/smp24dhl/.conda/envs/cosmos/bin/cobaya-run", line 8, in <module>
    sys.exit(run_script())
  File "/users/smp24dhl/.conda/envs/cosmos/lib/python3.9/site-packages/cobaya/run.py", line 198, in run_script
    run(info, **arguments.__dict__)
  File "/users/smp24dhl/.conda/envs/cosmos/lib/python3.9/site-packages/cobaya/run.py", line 123, in run
    with Model(updated_info["params"], updated_info["likelihood"],
  File "/users/smp24dhl/.conda/envs/cosmos/lib/python3.9/site-packages/cobaya/model.py", line 241, in __init__
    self.prior = Prior(self.parameterization, self._updated_info.get("prior"))
  File "/users/smp24dhl/.conda/envs/cosmos/lib/python3.9/site-packages/cobaya/prior.py", line 497, in __init__
    raise LoggedError(self.log, err, name, list(unknown))
cobaya.log.LoggedError: Some arguments of the external prior 'cal_dip_prior' cannot be found and don't have a default value either: ['A_act']
-------------------------------------------------------------

[2 : exception handler] ---------------------------------------

Traceback (most recent call last):
  File "/users/smp24dhl/.conda/envs/cosmos/bin/cobaya-run", line 8, in <module>
    sys.exit(run_script())
  File "/users/smp24dhl/.conda/envs/cosmos/lib/python3.9/site-packages/cobaya/run.py", line 198, in run_script
    run(info, **arguments.__dict__)
  File "/users/smp24dhl/.conda/envs/cosmos/lib/python3.9/site-packages/cobaya/run.py", line 123, in run
    with Model(updated_info["params"], updated_info["likelihood"],
  File "/users/smp24dhl/.conda/envs/cosmos/lib/python3.9/site-packages/cobaya/model.py", line 241, in __init__
    self.prior = Prior(self.parameterization, self._updated_info.get("prior"))
  File "/users/smp24dhl/.conda/envs/cosmos/lib/python3.9/site-packages/cobaya/prior.py", line 497, in __init__
    raise LoggedError(self.log, err, name, list(unknown))
cobaya.log.LoggedError: Some arguments of the external prior 'cal_dip_prior' cannot be found and don't have a default value either: ['A_act']
-------------------------------------------------------------

srun: error: node003: tasks 0-3: Exited with exit code 1
